Workbook

Sheet Статистика
A1: Объект: | C1: Название объекта
A2: Период замеров: | C2: с 03.07.2026 15:23 по 14.08.2026 14:59
A4: График мощности: | C4: Параллельный режим (активная мощность) | H4: Увеличить мощность: | J4: 0 | K4: =IF($C$4="Параллельный режим (активная мощность)","кВт","кВА") -> кВт
A6: Порог | B6: 8400 | C6: Выкл | D6: Порог | E6: 0 | F6: Вкл | G6: Порог | H6: 0 | I6: Выкл | J6: Порог | K6: 0 | L6: Выкл | M6: Выкл | N6: Порог | O6: 0 | P6: =IF($C$4="Параллельный режим (активная мощность)","кВт","кВА") -> кВт
A8: Медиана | B8: Вкл | C8: 0.5 | D8: Вкл | E8: 0.9 | F8: Вкл | G8: 0.99 | H8: Вкл | I8: Максимум | J8: Выкл
B10: Нижнее значение оси: | C10: 6000 | D10: =IF($C$4="Параллельный режим (активная мощность)","кВт","кВА") -> кВт | F10: Верхнее значение оси: | G10: 9000 | H10: =IF($C$4="Параллельный режим (активная мощность)","кВт","кВА") -> кВт
I13: ="Будние дни — "&IF($C$4="Параллельный режим (активная мощность)","Активная мощность, кВт","Полная мощность, кВА") -> Будние дни — Активная мощность, кВт
A14: =$C$10+(1)*($G$10-$C$10) -> 9000
A18: =$C$10+(0.8)*($G$10-$C$10) -> 8400
A22: =$C$10+(0.6)*($G$10-$C$10) -> 7800
A26: =$C$10+(0.4)*($G$10-$C$10) -> 7200
A30: =$C$10+(0.199999999999999)*($G$10-$C$10) -> 6600
A34: =$C$10+(0)*($G$10-$C$10) -> 6000
I38: ="Выходные/праздничные дни — "&IF($C$4="Параллельный режим (активная мощность)","Активная мощность, кВт","Полная мощность, кВА") -> Выходные/праздничные дни — Активная мощность, кВт
A39: =$C$10+(1)*($G$10-$C$10) -> 9000
A43: =$C$10+(0.8)*($G$10-$C$10) -> 8400
A47: =$C$10+(0.6)*($G$10-$C$10) -> 7800
A51: =$C$10+(0.4)*($G$10-$C$10) -> 7200
A55: =$C$10+(0.199999999999999)*($G$10-$C$10) -> 6600
A59: =$C$10+(0)*($G$10-$C$10) -> 6000

Sheet Данные
A1: time | B1: P0.5 | C1: P2.5 | D1: P5 | E1: P25 | F1: P50 | G1: P75 | H1: P95 | I1: P97.5 | J1: P99.5 | K1: Pmax | L1: Pmax_datetime | M1: S0.5 | N1: S2.5 | O1: S5 | P1: S25 | Q1: S50 | R1: S75 | S1: S95 | T1: S97.5 | U1: S99.5 | V1: Smax | W1: Smax_datetime | Y1: time | Z1: P0.5 | AA1: P2.5 | AB1: P5 | AC1: P25 | AD1: P50 | AE1: P75 | AF1: P95 | AG1: P97.5 | AH1: P99.5 | AI1: Pmax | AJ1: Pmax_datetime | AK1: S0.5 | AL1: S2.5 | AM1: S5 | AN1: S25 | AO1: S50 | AP1: S75 | AQ1: S95 | AR1: S97.5 | AS1: S99.5 | AT1: Smax | AU1: Smax_datetime | AW1: Base | AX1: Band99_L | AY1: Band90_L | AZ1: Band50_L | BA1: Band50_U | BB1: Band90_U | BC1: Band99_U | BD1: ScaleTop | BE1: Median | BF1: 50_low | BG1: 50_high | BH1: 90_low | BI1: 90_high | BJ1: 99_low | BK1: 99_high | BL1: Max | BM1: Thr1 | BN1: Thr2 | BO1: Thr3 | BP1: Thr4 | BQ1: Thr5 | BR1: ScaleAnchor | BS1: GlobalScale | BT1: Base | BU1: Band99_L | BV1: Band90_L | BW1: Band50_L | BX1: Band50_U | BY1: Band90_U | BZ1: Band99_U | CA1: ScaleTop | CB1: Median | CC1: 50_low | CD1: 50_high | CE1: 90_low | CF1: 90_high | CG1: 99_low | CH1: 99_high | CI1: Max | CJ1: Thr1 | CK1: Thr2 | CL1: Thr3 | CM1: Thr4 | CN1: Thr5 | CO1: ScaleAnchor
A2: 00:00 | B2: 2290.8497 | C2: 5613.8082 | D2: 7292.5853 | E2: 7621.1168 | F2: 7783.1093 | G2: 8076.8638 | H2: 8192.4126 | I2: 8281.9745 | J2: 8387.7881 | K2: 8499.35 | L2: 2026-07-08 00:00:00 | M2: 2840.8337 | N2: 6475.0355 | O2: 8299.629 | P2: 8689.133 | Q2: 8838.2227 | R2: 9074.0189 | S2: 9271.3581 | T2: 9345.0996 | U2: 9495.5733 | V2: 9623.24 | W2: 2026-07-08 00:00:00 | Y2: 00:00 | Z2: 7495.6794 | AA2: 7526.6007 | AB2: 7565.2523 | AC2: 7688.2531 | AD2: 7754.8011 | AE2: 7843.0706 | AF2: 8347.9849 | AG2: 8406.5495 | AH2: 8453.4011 | AI2: 8794.16 | AJ2: 2026-07-05 00:01:50 | AK2: 8510.6417 | AL2: 8545.8975 | AM2: 8589.9673 | AN2: 8737.407 | AO2: 8825.2686 | AP2: 8909.6073 | AQ2: 9444.1711 | AR2: 9509.9538 | AS2: 9562.5799 | AT2: 10021.62 | AU2: 2026-07-05 00:01:49 | AW2: =IF(A2="","",MAX(0,MIN(1,(((IF(Статистика!$C$4="Параллельный режим (активная мощность)",B2,M2)+Статистика!$J$4))-Статистика!$C$10)/MAX(Статистика!$G$10-Статистика!$C$10,0.000001)))) -> 0 | AX2: =IF(A2="","",MAX(0,MAX(0,MIN(1,(((IF(Статистика!$C$4="Параллельный режим (активная мощность)",D2,O2)+Статистика!$J$4))-Статистика!$C$10)/MAX(Статистика!$G$10-Статистика!$C$10,0.000001)))-MAX(0,MIN(1,(((IF(Статистика!$C$4="Параллельный режим (активная мощность)",B2,M2)+Статистика!$J$4))-Статистика!$C$10)/MAX(Статистика!$G$10-Статистика!$C$10,0.000001))))) -> 0.43086176 | AY2: =IF(A2="","",MAX(0,MAX(0,MIN(1,(((IF(Статистика!$C$4="Параллельный режим (активная мощность)",E2,P2)+Статистика!$J$4))-Статистика!$C$10)/MAX(Статистика!$G$10-Статистика!$C$10,0.000001)))-MAX(0,MIN(1,(((IF(Статистика!$C$4="Параллельный режим (активная мощность)",D2,O2)+Статистика!$J$4))-Статистика!$C$10)/MAX(Статистика!$G$10-Статистика!$C$10,0.000001))))) -> 0.10951053 | AZ2: =IF(A2="","",MAX(0,MAX(0,MIN(1,(((IF(Статистика!$C$4="Параллельный режим (активная мощность)",F2,Q2)+Статистика!$J$4))-Статистика!$C$10)/MAX(Статистика!$G$10-Статистика!$C$10,0.000001)))-MAX(0,MIN(1,(((IF(Статистика!$C$4="Параллельный режим (активная мощность)",E2,P2)+Статистика!$J$4))-Статистика!$C$10)/MAX(Статистика!$G$10-Статистика!$C$10,0.000001))))) -> 0.053997486 | BA2: =IF(A2="","",MAX(0,MAX(0,MIN(1,(((IF(Статистика!$C$4="Параллельный режим (активная мощность)",G2,R2)+Статистика!$J$4))-Статистика!$C$10)/MAX(Статистика!$G$10-Статистика!$C$10,0.000001)))-MAX(0,MIN(1,(((IF(Статистика!$C$4="Параллельный режим (активная мощность)",F2,Q2)+Статистика!$J$4))-Статистика!$C$10)/MAX(Статистика!$G$10-Статистика!$C$10,0.000001))))) -> 0.097918158 | BB2: =IF(A2="","",MAX(0,MAX(0,MIN(1,(((IF(Статистика!$C$4="Параллельный режим (активная мощность)",H2,S2)+Статистика!$J$4))-Статистика!$C$10)/MAX(Статистика!$G$10-Статистика!$C$10,0.000001)))-MAX(0,MIN(1,(((IF(Статистика!$C$4="Параллельный режим (активная мощность)",G2,R2)+Статистика!$J$4))-Статистика!$C$10)/MAX(Статистика!$G$10-Статистика!$C$10,0.000001))))) -> 0.038516261 | BC2: =IF(A2="","",MAX(0,MAX(0,MIN(1,(((IF(Статистика!$C$4="Параллельный режим (активная мощность)",J2,U2)+Статистика!$J$4))-Статистика!$C$10)/MAX(Статистика!$G$10-Статистика!$C$10,0.000001)))-MAX(0,MIN(1,(((IF(Статистика!$C$4="Параллельный режим (активная мощность)",H2,S2)+Статистика!$J$4))-Статистика!$C$10)/MAX(Статистика!$G$10-Статистика!$C$10,0.000001))))) -> 0.065125181 | BD2: =IF(A2="","",MAX(0,1-MAX(0,MIN(1,(((IF(Статистика!$C$4="Параллельный режим (активная мощность)",J2,U2)+Статистика!$J$4))-Статистика!$C$10)/MAX(Статистика!$G$10-Статистика!$C$10,0.000001))))) -> 0.20407063 | BE2: =IF(A2="",NA(),IF(Статистика!$B$8="Вкл",(((IF(Статистика!$C$4="Параллельный режим (активная мощность)",F2,Q2)+Статистика!$J$4))-Статистика!$C$10)/MAX(Статистика!$G$10-Статистика!$C$10,0.000001),NA())) -> 0.59436977 | BF2: =IF(A2="",NA(),IF(Статистика!$D$8="Вкл",(((IF(Статистика!$C$4="Параллельный режим (активная мощность)",E2,P2)+Статистика!$J$4))-Статистика!$C$10)/MAX(Статистика!$G$10-Статистика!$C$10,0.000001),NA())) -> 0.54037228 | BG2: =IF(A2="",NA(),IF(Статистика!$D$8="Вкл",(((IF(Статистика!$C$4="Параллельный режим (активная мощность)",G2,R2)+Статистика!$J$4))-Статистика!$C$10)/MAX(Статистика!$G$10-Статистика!$C$10,0.000001),NA())) -> 0.69228792 | BH2: =IF(A2="",NA(),IF(Статистика!$F$8="Вкл",(((IF(Статистика!$C$4="Параллельный режим (активная мощность)",D2,O2)+Статистика!$J$4))-Статистика!$C$10)/MAX(Статистика!$G$10-Статистика!$C$10,0.000001),NA())) -> 0.43086176 | BI2: =IF(A2="",NA(),IF(Статистика!$F$8="Вкл",(((IF(Статистика!$C$4="Параллельный режим (активная мощность)",H2,S2)+Статистика!$J$4))-Статистика!$C$10)/MAX(Статистика!$G$10-Статистика!$C$10,0.000001),NA())) -> 0.73080419 | BJ2: =IF(A2="",NA(),IF(Статистика!$H$8="Вкл",(((IF(Статистика!$C$4="Параллельный режим (активная мощность)",B2,M2)+Статистика!$J$4))-Статистика!$C$10)/MAX(Статистика!$G$10-Статистика!$C$10,0.000001),NA())) -> -1.2363834 | BK2: =IF(A2="",NA(),IF(Статистика!$H$8="Вкл",(((IF(Статистика!$C$4="Параллельный режим (активная мощность)",J2,U2)+Статистика!$J$4))-Статистика!$C$10)/MAX(Статистика!$G$10-Статистика!$C$10,0.000001),NA())) -> 0.79592937 | BL2: =IF(A2="",NA(),IF(Статистика!$J$8="Вкл",(((IF(Статистика!$C$4="Параллельный режим (активная мощность)",K2,V2)+Статистика!$J$4))-Статистика!$C$10)/MAX(Статистика!$G$10-Статистика!$C$10,0.000001),NA())) -> #N/A | BM2: =IF(AND(A2<>"",Статистика!$C$6="Вкл",Статистика!$B$6>0),(Статистика!$B$6-Статистика!$C$10)/MAX(Статистика!$G$10-Статистика!$C$10,0.000001),NA()) -> #N/A | BN2: =IF(AND(A2<>"",Статистика!$F$6="Вкл",Статистика!$E$6>0),(Статистика!$E$6-Статистика!$C$10)/MAX(Статистика!$G$10-Статистика!$C$10,0.000001),NA()) -> #N/A | BO2: =IF(AND(A2<>"",Статистика!$I$6="Вкл",Статистика!$H$6>0),(Статистика!$H$6-Статистика!$C$10)/MAX(Статистика!$G$10-Статистика!$C$10,0.000001),NA()) -> #N/A | BP2: =IF(AND(A2<>"",Статистика!$L$6="Вкл",Статистика!$K$6>0),(Статистика!$K$6-Статистика!$C$10)/MAX(Статистика!$G$10-Статистика!$C$10,0.000001),NA()) -> #N/A | BQ2: =IF(AND(A2<>"",Статистика!$M$6="Вкл",Статистика!$O$6>0),(Статистика!$O$6-Статистика!$C$10)/MAX(Статистика!$G$10-Статистика!$C$10,0.000001),NA()) -> #N/A | BR2: =IF(A2="",NA(),1) -> 1 | BS2: =Статистика!$G$10 -> 9000 | BT2: =IF(Y2="","",MAX(0,MIN(1,(((IF(Статистика!$C$4="Параллельный режим (активная мощность)",Z2,AK2)+Статистика!$J$4))-Статистика!$C$10)/MAX(Статистика!$G$10-Статистика!$C$10,0.000001)))) -> 0.49855979 | BU2: =IF(Y2="","",MAX(0,MAX(0,MIN(1,(((IF(Статистика!$C$4="Параллельный режим (активная мощность)",AB2,AM2)+Статистика!$J$4))-Статистика!$C$10)/MAX(Статистика!$G$10-Статистика!$C$10,0.000001)))-MAX(0,MIN(1,(((IF(Статистика!$C$4="Параллельный режим (активная мощность)",Z2,AK2)+Статистика!$J$4))-Статистика!$C$10)/MAX(Статистика!$G$10-Статистика!$C$10,0.000001))))) -> 0.023190987 | BV2: =IF(Y2="","",MAX(0,MAX(0,MIN(1,(((IF(Статистика!$C$4="Параллельный режим (активная мощность)",AC2,AN2)+Статистика!$J$4))-Статистика!$C$10)/MAX(Статистика!$G$10-Статистика!$C$10,0.000001)))-MAX(0,MIN(1,(((IF(Статистика!$C$4="Параллельный режим (активная мощность)",AB2,AM2)+Статистика!$J$4))-Статистика!$C$10)/MAX(Статистика!$G$10-Статистика!$C$10,0.000001))))) -> 0.041000268 | BW2: =IF(Y2="","",MAX(0,MAX(0,MIN(1,(((IF(Статистика!$C$4="Параллельный режим (активная мощность)",AD2,AO2)+Статистика!$J$4))-Статистика!$C$10)/MAX(Статистика!$G$10-Статистика!$C$10,0.000001)))-MAX(0,MIN(1,(((IF(Статистика!$C$4="Параллельный режим (активная мощность)",AC2,AN2)+Статистика!$J$4))-Статистика!$C$10)/MAX(Статистика!$G$10-Статистика!$C$10,0.000001))))) -> 0.022182669 | BX2: =IF(Y2="","",MAX(0,MAX(0,MIN(1,(((IF(Статистика!$C$4="Параллельный режим (активная мощность)",AE2,AP2)+Статистика!$J$4))-Статистика!$C$10)/MAX(Статистика!$G$10-Статистика!$C$10,0.000001)))-MAX(0,MIN(1,(((IF(Статистика!$C$4="Параллельный режим (активная мощность)",AD2,AO2)+Статистика!$J$4))-Статистика!$C$10)/MAX(Статистика!$G$10-Статистика!$C$10,0.000001))))) -> 0.029423167 | BY2: =IF(Y2="","",MAX(0,MAX(0,MIN(1,(((IF(Статистика!$C$4="Параллельный режим (активная мощность)",AF2,AQ2)+Статистика!$J$4))-Статистика!$C$10)/MAX(Статистика!$G$10-Статистика!$C$10,0.000001)))-MAX(0,MIN(1,(((IF(Статистика!$C$4="Параллельный режим (активная мощность)",AE2,AP2)+Статистика!$J$4))-Статистика!$C$10)/MAX(Статистика!$G$10-Статистика!$C$10,0.000001))))) -> 0.16830477 | BZ2: =IF(Y2="","",MAX(0,MAX(0,MIN(1,(((IF(Статистика!$C$4="Параллельный режим (активная мощность)",AH2,AS2)+Статистика!$J$4))-Статистика!$C$10)/MAX(Статистика!$G$10-Статистика!$C$10,0.000001)))-MAX(0,MIN(1,(((IF(Статистика!$C$4="Параллельный режим (активная мощность)",AF2,AQ2)+Статистика!$J$4))-Статистика!$C$10)/MAX(Статистика!$G$10-Статистика!$C$10,0.000001))))) -> 0.03513873 | CA2: =IF(Y2="","",MAX(0,1-MAX(0,MIN(1,(((IF(Статистика!$C$4="Параллельный режим (активная мощность)",AH2,AS2)+Статистика!$J$4))-Статистика!$C$10)/MAX(Статистика!$G$10-Статистика!$C$10,0.000001))))) -> 0.18219963 | CB2: =IF(Y2="",NA(),IF(Статистика!$B$8="Вкл",(((IF(Статистика!$C$4="Параллельный режим (активная мощность)",AD2,AO2)+Статистика!$J$4))-Статистика!$C$10)/MAX(Статистика!$G$10-Статистика!$C$10,0.000001),NA())) -> 0.58493371 | CC2: =IF(Y2="",NA(),IF(Статистика!$D$8="Вкл",(((IF(Статистика!$C$4="Параллельный режим (активная мощность)",AC2,AN2)+Статистика!$J$4))-Статистика!$C$10)/MAX(Статистика!$G$10-Статистика!$C$10,0.000001),NA())) -> 0.56275104 | CD2: =IF(Y2="",NA(),IF(Статистика!$D$8="Вкл",(((IF(Статистика!$C$4="Параллельный режим (активная мощность)",AE2,AP2)+Статистика!$J$4))-Статистика!$C$10)/MAX(Статистика!$G$10-Статистика!$C$10,0.000001),NA())) -> 0.61435688 | CE2: =IF(Y2="",NA(),IF(Статистика!$F$8="Вкл",(((IF(Статистика!$C$4="Параллельный режим (активная мощность)",AB2,AM2)+Статистика!$J$4))-Статистика!$C$10)/MAX(Статистика!$G$10-Статистика!$C$10,0.000001),NA())) -> 0.52175077 | CF2: =IF(Y2="",NA(),IF(Статистика!$F$8="Вкл",(((IF(Статистика!$C$4="Параллельный режим (активная мощность)",AF2,AQ2)+Статистика!$J$4))-Статистика!$C$10)/MAX(Статистика!$G$10-Статистика!$C$10,0.000001),NA())) -> 0.78266164 | CG2: =IF(Y2="",NA(),IF(Статистика!$H$8="Вкл",(((IF(Статистика!$C$4="Параллельный режим (активная мощность)",Z2,AK2)+Статистика!$J$4))-Статистика!$C$10)/MAX(Статистика!$G$10-Статистика!$C$10,0.000001),NA())) -> 0.49855979 | CH2: =IF(Y2="",NA(),IF(Статистика!$H$8="Вкл",(((IF(Статистика!$C$4="Параллельный режим (активная мощность)",AH2,AS2)+Статистика!$J$4))-Статистика!$C$10)/MAX(Статистика!$G$10-Статистика!$C$10,0.000001),NA())) -> 0.81780037 | CI2: =IF(Y2="",NA(),IF(Статистика!$J$8="Вкл",(((IF(Статистика!$C$4="Параллельный режим (активная мощность)",AI2,AT2)+Статистика!$J$4))-Статистика!$C$10)/MAX(Статистика!$G$10-Статистика!$C$10,0.000001),NA())) -> #N/A | CJ2: =IF(AND(Y2<>"",Статистика!$C$6="Вкл",Статистика!$B$6>0),(Статистика!$B$6-Статистика!$C$10)/MAX(Статистика!$G$10-Статистика!$C$10,0.000001),NA()) -> #N/A | CK2: =IF(AND(Y2<>"",Статистика!$F$6="Вкл",Статистика!$E$6>0),(Статистика!$E$6-Статистика!$C$10)/MAX(Статистика!$G$10-Статистика!$C$10,0.000001),NA()) -> #N/A | CL2: =IF(AND(Y2<>"",Статистика!$I$6="Вкл",Статистика!$H$6>0),(Статистика!$H$6-Статистика!$C$10)/MAX(Статистика!$G$10-Статистика!$C$10,0.000001),NA()) -> #N/A | CM2: =IF(AND(Y2<>"",Статистика!$L$6="Вкл",Статистика!$K$6>0),(Статистика!$K$6-Статистика!$C$10)/MAX(Статистика!$G$10-Статистика!$C$10,0.000001),NA()) -> #N/A | CN2: =IF(AND(Y2<>"",Статистика!$M$6="Вкл",Статистика!$O$6>0),(Статистика!$O$6-Статистика!$C$10)/MAX(Статистика!$G$10-Статистика!$C$10,0.000001),NA()) -> #N/A | CO2: =IF(Y2="",NA(),1) -> 1
A3: 00:05 | B3: 2277.0491 | C3: 5612.8994 | D3: 7326.6058 | E3: 7687.4257 | F3: 7819.9025 | G3: 8084.8903 | H3: 8285.4436 | I3: 8336.0571 | J3: 8382.4363 | K3: 8507.19 | L3: 2026-07-08 00:09:37 | M3: 2831.2581 | N3: 6487.2006 | O3: 8337.3426 | P3: 8724.6841 | Q3: 8871.7631 | R3: 9145.6437 | S3: 9355.6514 | T3: 9422.3766 | U3: 9502.2438 | V3: 9658.15 | W3: 2026-07-08 00:09:37 | Y3: 00:05 | Z3: 7472.5165 | AA3: 7529.7857 | AB3: 7601.3722 | AC3: 7733.6933 | AD3: 7824.4736 | AE3: 7949.1735 | AF3: 8365.3861 | AG3: 8442.327 | AH3: 8503.8797 | AI3: 8604.53 | AJ3: 2026-07-05 00:06:13 | AK3: 8481.0515 | AL3: 8549.1597 | AM3: 8634.2948 | AN3: 8809.5934 | AO3: 8882.4382 | AP3: 9044.3137 | AQ3: 9480.494 | AR3: 9566.2579 | AS3: 9634.8691 | AT3: 9823.45 | AU3: 2026-07-04 00:07:05 | AW3: =IF(A3="","",MAX(0,MIN(1,(((IF(Статистика!$C$4="Параллельный режим (активная мощность)",B3,M3)+Статистика!$J$4))-Статистика!$C$10)/MAX(Статистика!$G$10-Статистика!$C$10,0.000001)))) -> 0 | AX3: =IF(A3="","",MAX(0,MAX(0,MIN(1,(((IF(Статистика!$C$4="Параллельный режим (активная мощность)",D3,O3)+Статистика!$J$4))-Статистика!$C$10)/MAX(Статистика!$G$10-Статистика!$C$10,0.000001)))-MAX(0,MIN(1,(((IF(Статистика!$C$4="Параллельный режим (активная мощность)",B3,M3)+Статистика!$J$4))-Статистика!$C$10)/MAX(Статистика!$G$10-Статистика!$C$10,0.000001))))) -> 0.44220193 | AY3: =IF(A3="","",MAX(0,MAX(0,MIN(1,(((IF(Статистика!$C$4="Параллельный режим (активная мощность)",E3,P3)+Статистика!$J$4))-Статистика!$C$10)/MAX(Статистика!$G$10-Статистика!$C$10,0.000001)))-MAX(0,MIN(1,(((IF(Статистика!$C$4="Параллельный режим (активная мощность)",D3,O3)+Статистика!$J$4))-Статистика!$C$10)/MAX(Статистика!$G$10-Статистика!$C$10,0.000001))))) -> 0.12027331 | AZ3: =IF(A3="","",MAX(0,MAX(0,MIN(1,(((IF(Статистика!$C$4="Параллельный режим (активная мощность)",F3,Q3)+Статистика!$J$4))-Статистика!$C$10)/MAX(Статистика!$G$10-Статистика!$C$10,0.000001)))-MAX(0,MIN(1,(((IF(Статистика!$C$4="Параллельный режим (активная мощность)",E3,P3)+Статистика!$J$4))-Статистика!$C$10)/MAX(Статистика!$G$10-Статистика!$C$10,0.000001))))) -> 0.044158919 | BA3: =IF(A3="","",MAX(0,MAX(0,MIN(1,(((IF(Статистика!$C$4="Параллельный режим (активная мощность)",G3,R3)+Статистика!$J$4))-Статистика!$C$10)/MAX(Статистика!$G$10-Статистика!$C$10,0.000001)))-MAX(0,MIN(1,(((IF(Статистика!$C$4="Параллельный режим (активная мощность)",F3,Q3)+Статистика!$J$4))-Статистика!$C$10)/MAX(Статистика!$G$10-Статистика!$C$10,0.000001))))) -> 0.088329256 | BB3: =IF(A3="","",MAX(0,MAX(0,MIN(1,(((IF(Статистика!$C$4="Параллельный режим (активная мощность)",H3,S3)+Статистика!$J$4))-Статистика!$C$10)/MAX(Статистика!$G$10-Статистика!$C$10,0.000001)))-MAX(0,MIN(1,(((IF(Статистика!$C$4="Параллельный режим (активная мощность)",G3,R3)+Статистика!$J$4))-Статистика!$C$10)/MAX(Статистика!$G$10-Статистика!$C$10,0.000001))))) -> 0.066851102 | BC3: =IF(A3="","",MAX(0,MAX(0,MIN(1,(((IF(Статистика!$C$4="Параллельный режим (активная мощность)",J3,U3)+Статистика!$J$4))-Статистика!$C$10)/MAX(Статистика!$G$10-Статистика!$C$10,0.000001)))-MAX(0,MIN(1,(((IF(Статистика!$C$4="Параллельный режим (активная мощность)",H3,S3)+Статистика!$J$4))-Статистика!$C$10)/MAX(Статистика!$G$10-Статистика!$C$10,0.000001))))) -> 0.032330931 | BD3: =IF(A3="","",MAX(0,1-MAX(0,MIN(1,(((IF(Статистика!$C$4="Параллельный режим (активная мощность)",J3,U3)+Статистика!$J$4))-Статистика!$C$10)/MAX(Статистика!$G$10-Статистика!$C$10,0.000001))))) -> 0.20585455 | BE3: =IF(A3="",NA(),IF(Статистика!$B$8="Вкл",(((IF(Статистика!$C$4="Параллельный режим (активная мощность)",F3,Q3)+Статистика!$J$4))-Статистика!$C$10)/MAX(Статистика!$G$10-Статистика!$C$10,0.000001),NA())) -> 0.60663416 | BF3: =IF(A3="",NA(),IF(Статистика!$D$8="Вкл",(((IF(Статистика!$C$4="Параллельный режим (активная мощность)",E3,P3)+Статистика!$J$4))-Статистика!$C$10)/MAX(Статистика!$G$10-Статистика!$C$10,0.000001),NA())) -> 0.56247524 | BG3: =IF(A3="",NA(),IF(Статистика!$D$8="Вкл",(((IF(Статистика!$C$4="Параллельный режим (активная мощность)",G3,R3)+Статистика!$J$4))-Статистика!$C$10)/MAX(Статистика!$G$10-Статистика!$C$10,0.000001),NA())) -> 0.69496342 | BH3: =IF(A3="",NA(),IF(Статистика!$F$8="Вкл",(((IF(Статистика!$C$4="Параллельный режим (активная мощность)",D3,O3)+Статистика!$J$4))-Статистика!$C$10)/MAX(Статистика!$G$10-Статистика!$C$10,0.000001),NA())) -> 0.44220193 | BI3: =IF(A3="",NA(),IF(Статистика!$F$8="Вкл",(((IF(Статистика!$C$4="Параллельный режим (активная мощность)",H3,S3)+Статистика!$J$4))-Статистика!$C$10)/MAX(Статистика!$G$10-Статистика!$C$10,0.000001),NA())) -> 0.76181452 | BJ3: =IF(A3="",NA(),IF(Статистика!$H$8="Вкл",(((IF(Статистика!$C$4="Параллельный режим (активная мощность)",B3,M3)+Статистика!$J$4))-Статистика!$C$10)/MAX(Статистика!$G$10-Статистика!$C$10,0.000001),NA())) -> -1.2409836 | BK3: =IF(A3="",NA(),IF(Статистика!$H$8="Вкл",(((IF(Статистика!$C$4="Параллельный режим (активная мощность)",J3,U3)+Статистика!$J$4))-Статистика!$C$10)/MAX(Статистика!$G$10-Статистика!$C$10,0.000001),NA())) -> 0.79414545 | BL3: =IF(A3="",NA(),IF(Статистика!$J$8="Вкл",(((IF(Статистика!$C$4="Параллельный режим (активная мощность)",K3,V3)+Статистика!$J$4))-Статистика!$C$10)/MAX(Статистика!$G$10-Статистика!$C$10,0.000001),NA())) -> #N/A | BM3: =IF(AND(A3<>"",Статистика!$C$6="Вкл",Статистика!$B$6>0),(Статистика!$B$6-Статистика!$C$10)/MAX(Статистика!$G$10-Статистика!$C$10,0.000001),NA()) -> #N/A | BN3: =IF(AND(A3<>"",Статистика!$F$6="Вкл",Статистика!$E$6>0),(Статистика!$E$6-Статистика!$C$10)/MAX(Статистика!$G$10-Статистика!$C$10,0.000001),NA()) -> #N/A | BO3: =IF(AND(A3<>"",Статистика!$I$6="Вкл",Статистика!$H$6>0),(Статистика!$H$6-Статистика!$C$10)/MAX(Статистика!$G$10-Статистика!$C$10,0.000001),NA()) -> #N/A | BP3: =IF(AND(A3<>"",Статистика!$L$6="Вкл",Статистика!$K$6>0),(Статистика!$K$6-Статистика!$C$10)/MAX(Статистика!$G$10-Статистика!$C$10,0.000001),NA()) -> #N/A | BQ3: =IF(AND(A3<>"",Статистика!$M$6="Вкл",Статистика!$O$6>0),(Статистика!$O$6-Статистика!$C$10)/MAX(Статистика!$G$10-Статистика!$C$10,0.000001),NA()) -> #N/A | BR3: =IF(A3="",NA(),1) -> 1 | BT3: =IF(Y3="","",MAX(0,MIN(1,(((IF(Статистика!$C$4="Параллельный режим (активная мощность)",Z3,AK3)+Статистика!$J$4))-Статистика!$C$10)/MAX(Статистика!$G$10-Статистика!$C$10,0.000001)))) -> 0.49083882 | BU3: =IF(Y3="","",MAX(0,MAX(0,MIN(1,(((IF(Статистика!$C$4="Параллельный режим (активная мощность)",AB3,AM3)+Статистика!$J$4))-Статистика!$C$10)/MAX(Статистика!$G$10-Статистика!$C$10,0.000001)))-MAX(0,MIN(1,(((IF(Статистика!$C$4="Параллельный режим (активная мощность)",Z3,AK3)+Статистика!$J$4))-Статистика!$C$10)/MAX(Статистика!$G$10-Статистика!$C$10,0.000001))))) -> 0.042951909 | BV3: =IF(Y3="","",MAX(0,MAX(0,MIN(1,(((IF(Статистика!$C$4="Параллельный режим (активная мощность)",AC3,AN3)+Статистика!$J$4))-Статистика!$C$10)/MAX(Статистика!$G$10-Статистика!$C$10,0.000001)))-MAX(0,MIN(1,(((IF(Статистика!$C$4="Параллельный режим (активная мощность)",AB3,AM3)+Статистика!$J$4))-Статистика!$C$10)/MAX(Статистика!$G$10-Статистика!$C$10,0.000001))))) -> 0.044107043 | BW3: =IF(Y3="","",MAX(0,MAX(0,MIN(1,(((IF(Статистика!$C$4="Параллельный режим (активная мощность)",AD3,AO3)+Статистика!$J$4))-Статистика!$C$10)/MAX(Статистика!$G$10-Статистика!$C$10,0.000001)))-MAX(0,MIN(1,(((IF(Статистика!$C$4="Параллельный режим (активная мощность)",AC3,AN3)+Статистика!$J$4))-Статистика!$C$10)/MAX(Статистика!$G$10-Статистика!$C$10,0.000001))))) -> 0.030260086 | BX3: =IF(Y3="","",MAX(0,MAX(0,MIN(1,(((IF(Статистика!$C$4="Параллельный режим (активная мощность)",AE3,AP3)+Статистика!$J$4))-Статистика!$C$10)/MAX(Статистика!$G$10-Статистика!$C$10,0.000001)))-MAX(0,MIN(1,(((IF(Статистика!$C$4="Параллельный режим (активная мощность)",AD3,AO3)+Статистика!$J$4))-Статистика!$C$10)/MAX(Статистика!$G$10-Статистика!$C$10,0.000001))))) -> 0.041566622 | BY3: =IF(Y3="","",MAX(0,MAX(0,MIN(1,(((IF(Статистика!$C$4="Параллельный режим (активная мощность)",AF3,AQ3)+Статистика!$J$4))-Статистика!$C$10)/MAX(Статистика!$G$10-Статистика!$C$10,0.000001)))-MAX(0,MIN(1,(((IF(Статистика!$C$4="Параллельный режим (активная мощность)",AE3,AP3)+Статистика!$J$4))-Статистика!$C$10)/MAX(Статистика!$G$10-Статистика!$C$10,0.000001))))) -> 0.13873756 | BZ3: =IF(Y3="","",MAX(0,MAX(0,MIN(1,(((IF(Статистика!$C$4="Параллельный режим (активная мощность)",AH3,AS3)+Статистика!$J$4))-Статистика!$C$10)/MAX(Статистика!$G$10-Статистика!$C$10,0.000001)))-MAX(0,MIN(1,(((IF(Статистика!$C$4="Параллельный режим (активная мощность)",AF3,AQ3)+Статистика!$J$4))-Статистика!$C$10)/MAX(Статистика!$G$10-Статистика!$C$10,0.000001))))) -> 0.04616452 | CA3: =IF(Y3="","",MAX(0,1-MAX(0,MIN(1,(((IF(Статистика!$C$4="Параллельный режим (активная мощность)",AH3,AS3)+Статистика!$J$4))-Статистика!$C$10)/MAX(Статистика!$G$10-Статистика!$C$10,0.000001))))) -> 0.16537344 | CB3: =IF(Y3="",NA(),IF(Статистика!$B$8="Вкл",(((IF(Статистика!$C$4="Параллельный режим (активная мощность)",AD3,AO3)+Статистика!$J$4))-Статистика!$C$10)/MAX(Статистика!$G$10-Статистика!$C$10,0.000001),NA())) -> 0.60815786 | CC3: =IF(Y3="",NA(),IF(Статистика!$D$8="Вкл",(((IF(Статистика!$C$4="Параллельный режим (активная мощность)",AC3,AN3)+Статистика!$J$4))-Статистика!$C$10)/MAX(Статистика!$G$10-Статистика!$C$10,0.000001),NA())) -> 0.57789778 | CD3: =IF(Y3="",NA(),IF(Статистика!$D$8="Вкл",(((IF(Статистика!$C$4="Параллельный режим (активная мощность)",AE3,AP3)+Статистика!$J$4))-Статистика!$C$10)/MAX(Статистика!$G$10-Статистика!$C$10,0.000001),NA())) -> 0.64972448 | CE3: =IF(Y3="",NA(),IF(Статистика!$F$8="Вкл",(((IF(Статистика!$C$4="Параллельный режим (активная мощность)",AB3,AM3)+Статистика!$J$4))-Статистика!$C$10)/MAX(Статистика!$G$10-Статистика!$C$10,0.000001),NA())) -> 0.53379073 | CF3: =IF(Y3="",NA(),IF(Статистика!$F$8="Вкл",(((IF(Статистика!$C$4="Параллельный режим (активная мощность)",AF3,AQ3)+Статистика!$J$4))-Статистика!$C$10)/MAX(Статистика!$G$10-Статистика!$C$10,0.000001),NA())) -> 0.78846205 | CG3: =IF(Y3="",NA(),IF(Статистика!$H$8="Вкл",(((IF(Статистика!$C$4="Параллельный режим (активная мощность)",Z3,AK3)+Статистика!$J$4))-Статистика!$C$10)/MAX(Статистика!$G$10-Статистика!$C$10,0.000001),NA())) -> 0.49083882 | CH3: =IF(Y3="",NA(),IF(Статистика!$H$8="Вкл",(((IF(Статистика!$C$4="Параллельный режим (активная мощность)",AH3,AS3)+Статистика!$J$4))-Статистика!$C$10)/MAX(Статистика!$G$10-Статистика!$C$10,0.000001),NA())) -> 0.83462656 | CI3: =IF(Y3="",NA(),IF(Статистика!$J$8="Вкл",(((IF(Статистика!$C$4="Параллельный режим (активная мощность)",AI3,AT3)+Статистика!$J$4))-Статистика!$C$10)/MAX(Статистика!$G$10-Статистика!$C$10,0.000001),NA())) -> #N/A | CJ3: =IF(AND(Y3<>"",Статистика!$C$6="Вкл",Статистика!$B$6>0),(Статистика!$B$6-Статистика!$C$10)/MAX(Статистика!$G$10-Статистика!$C$10,0.000001),NA()) -> #N/A | CK3: =IF(AND(Y3<>"",Статистика!$F$6="Вкл",Статистика!$E$6>0),(Статистика!$E$6-Статистика!$C$10)/MAX(Статистика!$G$10-Статистика!$C$10,0.000001),NA()) -> #N/A | CL3: =IF(AND(Y3<>"",Статистика!$I$6="Вкл",Статистика!$H$6>0),(Статистика!$H$6-Статистика!$C$10)/MAX(Статистика!$G$10-Статистика!$C$10,0.000001),NA()) -> #N/A | CM3: =IF(AND(Y3<>"",Статистика!$L$6="Вкл",Статистика!$K$6>0),(Статистика!$K$6-Статистика!$C$10)/MAX(Статистика!$G$10-Статистика!$C$10,0.000001),NA()) -> #N/A | CN3: =IF(AND(Y3<>"",Статистика!$M$6="Вкл",Статистика!$O$6>0),(Статистика!$O$6-Статистика!$C$10)/MAX(Статистика!$G$10-Статистика!$C$10,0.000001),NA()) -> #N/A | CO3: =IF(Y3="",NA(),1) -> 1
A4: 00:10 | B4: 2309.6954 | C4: 5684.2224 | D4: 7351.9307 | E4: 7680.2178 | F4: 7895.9935 | G4: 8079.1563 | H4: 8322.074 | I4: 8385.6085 | J4: 8473.5702 | K4: 8703 | L4: 2026-07-08 00:10:29 | M4: 2873.9088 | N4: 6564.099 | O4: 8387.7145 | P4: 8737.7408 | Q4: 8961.6285 | R4: 9116.4824 | S4: 9382.8915 | T4: 9473.8061 | U4: 9647.2799 | V4: 9971.05 | W4: 2026-07-08 00:10:29 | Y4: 00:10 | Z4: 7563.5629 | AA4: 7605.2009 | AB4: 7657.2485 | AC4: 7786.4586 | AD4: 7847.512 | AE4: 7975.774 | AF4: 8419.6253 | AG4: 8479.5971 | AH4: 8527.5746 | AI4: 8619.68 | AJ4: 2026-07-05 00:14:54 | AK4: 8631.3469 | AL4: 8670.3816 | AM4: 8719.1749 | AN4: 8903.0542 | AO4: 8990.2963 | AP4: 9059.2343 | AQ4: 9554.4391 | AR4: 9610.1245 | AS4: 9654.6728 | AT4: 9747.18 | AU4: 2026-07-05 00:14:54 | AW4: =IF(A4="","",MAX(0,MIN(1,(((IF(Статистика!$C$4="Параллельный режим (активная мощность)",B4,M4)+Статистика!$J$4))-Статистика!$C$10)/MAX(Статистика!$G$10-Статистика!$C$10,0.000001)))) -> 0 | AX4: =IF(A4="","",MAX(0,MAX(0,MIN(1,(((IF(Статистика!$C$4="Параллельный режим (активная мощность)",D4,O4)+Статистика!$J$4))-Статистика!$C$10)/MAX(Статистика!$G$10-Статистика!$C$10,0.000001)))-MAX(0,MIN(1,(((IF(Статистика!$C$4="Параллельный режим (активная мощность)",B4,M4)+Статистика!$J$4))-Статистика!$C$10)/MAX(Статистика!$G$10-Статистика!$C$10,0.000001))))) -> 0.45064356 | AY4: =IF(A4="","",MAX(0,MAX(0,MIN(1,(((IF(Статистика!$C$4="Параллельный режим (активная мощность)",E4,P4)+Статистика!$J$4))-Статистика!$C$10)/MAX(Статистика!$G$10-Статистика!$C$10,0.000001)))-MAX(0,MIN(1,(((IF(Статистика!$C$4="Параллельный режим (активная мощность)",D4,O4)+Статистика!$J$4))-Статистика!$C$10)/MAX(Статистика!$G$10-Статистика!$C$10,0.000001))))) -> 0.10942905 | AZ4: =IF(A4="","",MAX(0,MAX(0,MIN(1,(((IF(Статистика!$C$4="Параллельный режим (активная мощность)",F4,Q4)+Статистика!$J$4))-Статистика!$C$10)/MAX(Статистика!$G$10-Статистика!$C$10,0.000001)))-MAX(0,MIN(1,(((IF(Статистика!$C$4="Параллельный режим (активная мощность)",E4,P4)+Статистика!$J$4))-Статистика!$C$10)/MAX(Статистика!$G$10-Статистика!$C$10,0.000001))))) -> 0.071925222 | BA4: =IF(A4="","",MAX(0,MAX(0,MIN(1,(((IF(Статистика!$C$4="Параллельный режим (активная мощность)",G4,R4)+Статистика!$J$4))-Статистика!$C$10)/MAX(Статистика!$G$10-Статистика!$C$10,0.000001)))-MAX(0,MIN(1,(((IF(Статистика!$C$4="Параллельный режим (активная мощность)",F4,Q4)+Статистика!$J$4))-Статистика!$C$10)/MAX(Статистика!$G$10-Статистика!$C$10,0.000001))))) -> 0.061054264 | BB4: =IF(A4="","",MAX(0,MAX(0,MIN(1,(((IF(Статистика!$C$4="Параллельный режим (активная мощность)",H4,S4)+Статистика!$J$4))-Статистика!$C$10)/MAX(Статистика!$G$10-Статистика!$C$10,0.000001)))-MAX(0,MIN(1,(((IF(Статистика!$C$4="Параллельный режим (активная мощность)",G4,R4)+Статистика!$J$4))-Статистика!$C$10)/MAX(Статистика!$G$10-Статистика!$C$10,0.000001))))) -> 0.080972573 | BC4: =IF(A4="","",MAX(0,MAX(0,MIN(1,(((IF(Статистика!$C$4="Параллельный режим (активная мощность)",J4,U4)+Статистика!$J$4))-Статистика!$C$10)/MAX(Статистика!$G$10-Статистика!$C$10,0.000001)))-MAX(0,MIN(1,(((IF(Статистика!$C$4="Параллельный режим (активная мощность)",H4,S4)+Статистика!$J$4))-Статистика!$C$10)/MAX(Статистика!$G$10-Статистика!$C$10,0.000001))))) -> 0.050498744 | BD4: =IF(A4="","",MAX(0,1-MAX(0,MIN(1,(((IF(Статистика!$C$4="Параллельный режим (активная мощность)",J4,U4)+Статистика!$J$4))-Статистика!$C$10)/MAX(Статистика!$G$10-Статистика!$C$10,0.000001))))) -> 0.17547659 | BE4: =IF(A4="",NA(),IF(Статистика!$B$8="Вкл",(((IF(Статистика!$C$4="Параллельный режим (активная мощность)",F4,Q4)+Статистика!$J$4))-Статистика!$C$10)/MAX(Статистика!$G$10-Статистика!$C$10,0.000001),NA())) -> 0.63199783 | BF4: =IF(A4="",NA(),IF(Статистика!$D$8="Вкл",(((IF(Статистика!$C$4="Параллельный режим (активная мощность)",E4,P4)+Статистика!$J$4))-Статистика!$C$10)/MAX(Статистика!$G$10-Статистика!$C$10,0.000001),NA())) -> 0.56007261 | BG4: =IF(A4="",NA(),IF(Статистика!$D$8="Вкл",(((IF(Статистика!$C$4="Параллельный режим (активная мощность)",G4,R4)+Статистика!$J$4))-Статистика!$C$10)/MAX(Статистика!$G$10-Статистика!$C$10,0.000001),NA())) -> 0.6930521 | BH4: =IF(A4="",NA(),IF(Статистика!$F$8="Вкл",(((IF(Статистика!$C$4="Параллельный режим (активная мощность)",D4,O4)+Статистика!$J$4))-Статистика!$C$10)/MAX(Статистика!$G$10-Статистика!$C$10,0.000001),NA())) -> 0.45064356 | BI4: =IF(A4="",NA(),IF(Статистика!$F$8="Вкл",(((IF(Статистика!$C$4="Параллельный режим (активная мощность)",H4,S4)+Статистика!$J$4))-Статистика!$C$10)/MAX(Статистика!$G$10-Статистика!$C$10,0.000001),NA())) -> 0.77402467 | BJ4: =IF(A4="",NA(),IF(Статистика!$H$8="Вкл",(((IF(Статистика!$C$4="Параллельный режим (активная мощность)",B4,M4)+Статистика!$J$4))-Статистика!$C$10)/MAX(Статистика!$G$10-Статистика!$C$10,0.000001),NA())) -> -1.2301015 | BK4: =IF(A4="",NA(),IF(Статистика!$H$8="Вкл",(((IF(Статистика!$C$4="Параллельный режим (активная мощность)",J4,U4)+Статистика!$J$4))-Статистика!$C$10)/MAX(Статистика!$G$10-Статистика!$C$10,0.000001),NA())) -> 0.82452341 | BL4: =IF(A4="",NA(),IF(Статистика!$J$8="Вкл",(((IF(Статистика!$C$4="Параллельный режим (активная мощность)",K4,V4)+Статистика!$J$4))-Статистика!$C$10)/MAX(Статистика!$G$10-Статистика!$C$10,0.000001),NA())) -> #N/A | BM4: =IF(AND(A4<>"",Статистика!$C$6="Вкл",Статистика!$B$6>0),(Статистика!$B$6-Статистика!$C$10)/MAX(Статистика!$G$10-Статистика!$C$10,0.000001),NA()) -> #N/A | BN4: =IF(AND(A4<>"",Статистика!$F$6="Вкл",Статистика!$E$6>0),(Статистика!$E$6-Статистика!$C$10)/MAX(Статистика!$G$10-Статистика!$C$10,0.000001),NA()) -> #N/A | BO4: =IF(AND(A4<>"",Статистика!$I$6="Вкл",Статистика!$H$6>0),(Статистика!$H$6-Статистика!$C$10)/MAX(Статистика!$G$10-Статистика!$C$10,0.000001),NA()) -> #N/A | BP4: =IF(AND(A4<>"",Статистика!$L$6="Вкл",Статистика!$K$6>0),(Статистика!$K$6-Статистика!$C$10)/MAX(Статистика!$G$10-Статистика!$C$10,0.000001),NA()) -> #N/A | BQ4: =IF(AND(A4<>"",Статистика!$M$6="Вкл",Статистика!$O$6>0),(Статистика!$O$6-Статистика!$C$10)/MAX(Статистика!$G$10-Статистика!$C$10,0.000001),NA()) -> #N/A | BR4: =IF(A4="",NA(),1) -> 1 | BT4: =IF(Y4="","",MAX(0,MIN(1,(((IF(Статистика!$C$4="Параллельный режим (активная мощность)",Z4,AK4)+Статистика!$J$4))-Статистика!$C$10)/MAX(Статистика!$G$10-Статистика!$C$10,0.000001)))) -> 0.52118762 | BU4: =IF(Y4="","",MAX(0,MAX(0,MIN(1,(((IF(Статистика!$C$4="Параллельный режим (активная мощность)",AB4,AM4)+Статистика!$J$4))-Статистика!$C$10)/MAX(Статистика!$G$10-Статистика!$C$10,0.000001)))-MAX(0,MIN(1,(((IF(Статистика!$C$4="Параллельный режим (активная мощность)",Z4,AK4)+Статистика!$J$4))-Статистика!$C$10)/MAX(Статистика!$G$10-Статистика!$C$10,0.000001))))) -> 0.031228555 | BV4: =IF(Y4="","",MAX(0,MAX(0,MIN(1,(((IF(Статистика!$C$4="Параллельный режим (активная мощность)",AC4,AN4)+Статистика!$J$4))-Статистика!$C$10)/MAX(Статистика!$G$10-Статистика!$C$10,0.000001)))-MAX(0,MIN(1,(((IF(Статистика!$C$4="Параллельный режим (активная мощность)",AB4,AM4)+Статистика!$J$4))-Статистика!$C$10)/MAX(Статистика!$G$10-Статистика!$C$10,0.000001))))) -> 0.043070042 | BW4: =IF(Y4="","",MAX(0,MAX(0,MIN(1,(((IF(Статистика!$C$4="Параллельный режим (активная мощность)",AD4,AO4)+Статистика!$J$4))-Статистика!$C$10)/MAX(Статистика!$G$10-Статистика!$C$10,0.000001)))-MAX(0,MIN(1,(((IF(Статистика!$C$4="Параллельный режим (активная мощность)",AC4,AN4)+Статистика!$J$4))-Статистика!$C$10)/MAX(Статистика!$G$10-Статистика!$C$10,0.000001))))) -> 0.020351108 | BX4: =IF(Y4="","",MAX(0,MAX(0,MIN(1,(((IF(Статистика!$C$4="Параллельный режим (активная мощность)",AE4,AP4)+Статистика!$J$4))-Статистика!$C$10)/MAX(Статистика!$G$10-Статистика!$C$10,0.000001)))-MAX(0,MIN(1,(((IF(Статистика!$C$4="Параллельный режим (активная мощность)",AD4,AO4)+Статистика!$J$4))-Статистика!$C$10)/MAX(Статистика!$G$10-Статистика!$C$10,0.000001))))) -> 0.042753997 | BY4: =IF(Y4="","",MAX(0,MAX(0,MIN(1,(((IF(Статистика!$C$4="Параллельный режим (активная мощность)",AF4,AQ4)+Статистика!$J$4))-Статистика!$C$10)/MAX(Статистика!$G$10-Статистика!$C$10,0.000001)))-MAX(0,MIN(1,(((IF(Статистика!$C$4="Параллельный режим (активная мощность)",AE4,AP4)+Статистика!$J$4))-Статистика!$C$10)/MAX(Статистика!$G$10-Статистика!$C$10,0.000001))))) -> 0.14795044 | BZ4: =IF(Y4="","",MAX(0,MAX(0,MIN(1,(((IF(Статистика!$C$4="Параллельный режим (активная мощность)",AH4,AS4)+Статистика!$J$4))-Статистика!$C$10)/MAX(Статистика!$G$10-Статистика!$C$10,0.000001)))-MAX(0,MIN(1,(((IF(Статистика!$C$4="Параллельный режим (активная мощность)",AF4,AQ4)+Статистика!$J$4))-Статистика!$C$10)/MAX(Статистика!$G$10-Статистика!$C$10,0.000001))))) -> 0.035983106 | CA4: =IF(Y4="","",MAX(0,1-MAX(0,MIN(1,(((IF(Статистика!$C$4="Параллельный режим (активная мощность)",AH4,AS4)+Статистика!$J$4))-Статистика!$C$10)/MAX(Статистика!$G$10-Статистика!$C$10,0.000001))))) -> 0.15747513 | CB4: =IF(Y4="",NA(),IF(Статистика!$B$8="Вкл",(((IF(Статистика!$C$4="Параллельный режим (активная мощность)",AD4,AO4)+Статистика!$J$4))-Статистика!$C$10)/MAX(Статистика!$G$10-Статистика!$C$10,0.000001),NA())) -> 0.61583732 | CC4: =IF(Y4="",NA(),IF(Статистика!$D$8="Вкл",(((IF(Статистика!$C$4="Параллельный режим (активная мощность)",AC4,AN4)+Статистика!$J$4))-Статистика!$C$10)/MAX(Статистика!$G$10-Статистика!$C$10,0.000001),NA())) -> 0.59548621 | CD4: =IF(Y4="",NA(),IF(Статистика!$D$8="Вкл",(((IF(Статистика!$C$4="Параллельный режим (активная мощность)",AE4,AP4)+Статистика!$J$4))-Статистика!$C$10)/MAX(Статистика!$G$10-Статистика!$C$10,0.000001),NA())) -> 0.65859132 | CE4: =IF(Y4="",NA(),IF(Статистика!$F$8="Вкл",(((IF(Статистика!$C$4="Параллельный режим (активная мощность)",AB4,AM4)+Статистика!$J$4))-Статистика!$C$10)/MAX(Статистика!$G$10-Статистика!$C$10,0.000001),NA())) -> 0.55241617 | CF4: =IF(Y4="",NA(),IF(Статистика!$F$8="Вкл",(((IF(Статистика!$C$4="Параллельный режим (активная мощность)",AF4,AQ4)+Статистика!$J$4))-Статистика!$C$10)/MAX(Статистика!$G$10-Статистика!$C$10,0.000001),NA())) -> 0.80654176 | CG4: =IF(Y4="",NA(),IF(Статистика!$H$8="Вкл",(((IF(Статистика!$C$4="Параллельный режим (активная мощность)",Z4,AK4)+Статистика!$J$4))-Статистика!$C$10)/MAX(Статистика!$G$10-Статистика!$C$10,0.000001),NA())) -> 0.52118762 | CH4: =IF(Y4="",NA(),IF(Статистика!$H$8="Вкл",(((IF(Статистика!$C$4="Параллельный режим (активная мощность)",AH4,AS4)+Статистика!$J$4))-Статистика!$C$10)/MAX(Статистика!$G$10-Статистика!$C$10,0.000001),NA())) -> 0.84252487 | CI4: =IF(Y4="",NA(),IF(Статистика!$J$8="Вкл",(((IF(Статистика!$C$4="Параллельный режим (активная мощность)",AI4,AT4)+Статистика!$J$4))-Статистика!$C$10)/MAX(Статистика!$G$10-Статистика!$C$10,0.000001),NA())) -> #N/A | CJ4: =IF(AND(Y4<>"",Статистика!$C$6="Вкл",Статистика!$B$6>0),(Статистика!$B$6-Статистика!$C$10)/MAX(Статистика!$G$10-Статистика!$C$10,0.000001),NA()) -> #N/A | CK4: =IF(AND(Y4<>"",Статистика!$F$6="Вкл",Статистика!$E$6>0),(Статистика!$E$6-Статистика!$C$10)/MAX(Статистика!$G$10-Статистика!$C$10,0.000001),NA()) -> #N/A | CL4: =IF(AND(Y4<>"",Статистика!$I$6="Вкл",Статистика!$H$6>0),(Статистика!$H$6-Статистика!$C$10)/MAX(Статистика!$G$10-Статистика!$C$10,0.000001),NA()) -> #N/A | CM4: =IF(AND(Y4<>"",Статистика!$L$6="Вкл",Статистика!$K$6>0),(Статистика!$K$6-Статистика!$C$10)/MAX(Статистика!$G$10-Статистика!$C$10,0.000001),NA()) -> #N/A | CN4: =IF(AND(Y4<>"",Статистика!$M$6="Вкл",Статистика!$O$6>0),(Статистика!$O$6-Статистика!$C$10)/MAX(Статистика!$G$10-Статистика!$C$10,0.000001),NA()) -> #N/A | CO4: =IF(Y4="",NA(),1) -> 1
A5: 00:15 | B5: 2296.5409 | C5: 5686.8269 | D5: 7339.7976 | E5: 7682.79 | F5: 7885.1499 | G5: 8068.6305 | H5: 8420.1973 | I5: 8494.9979 | J5: 8520.8192 | K5: 8606.27 | L5: 2026-07-08 00:15:35 | M5: 2858.5413 | N5: 6565.521 | O5: 8380.9745 | P5: 8747.7304 | Q5: 8946.596 | R5: 9106.1478 | S5: 9482.9904 | T5: 9591.9578 | U5: 9690.5166 | V5: 9805.32 | W5: 2026-07-08 00:17:08 | Y5: 00:15 | Z5: 7584.6347 | AA5: 7614.4061 | AB5: 7651.6202 | AC5: 7815.0997 | AD5: 7899.7696 | AE5: 7931.4276 | AF5: 8398.8333 | AG5: 8453.008 | AH5: 8496.3477 | AI5: 8596.97 | AJ5: 2026-07-05 00:16:34 | AK5: 8686.7067 | AL5: 8707.4348 | AM5: 8733.3449 | AN5: 8918.3772 | AO5: 8987.664 | AP5: 9068.9449 | AQ5: 9511.4985 | AR5: 9568.8761 | AS5: 9614.7782 | AT5: 9733.56 | AU5: 2026-07-05 00:15:55 | AW5: =IF(A5="","",MAX(0,MIN(1,(((IF(Статистика!$C$4="Параллельный режим (активная мощность)",B5,M5)+Статистика!$J$4))-Статистика!$C$10)/MAX(Статистика!$G$10-Статистика!$C$10,0.000001)))) -> 0 | AX5: =IF(A5="","",MAX(0,MAX(0,MIN(1,(((IF(Статистика!$C$4="Параллельный режим (активная мощность)",D5,O5)+Статистика!$J$4))-Статистика!$C$10)/MAX(Статистика!$G$10-Статистика!$C$10,0.000001)))-MAX(0,MIN(1,(((IF(Статистика!$C$4="Параллельный режим (активная мощность)",B5,M5)+Статистика!$J$4))-Статистика!$C$10)/MAX(Статистика!$G$10-Статистика!$C$10,0.000001))))) -> 0.44659919 | AY5: =IF(A5="","",MAX(0,MAX(0,MIN(1,(((IF(Статистика!$C$4="Параллельный режим (активная мощность)",E5,P5)+Статистика!$J$4))-Статистика!$C$10)/MAX(Статистика!$G$10-Статистика!$C$10,0.000001)))-MAX(0,MIN(1,(((IF(Статистика!$C$4="Параллельный режим (активная мощность)",D5,O5)+Статистика!$J$4))-Статистика!$C$10)/MAX(Статистика!$G$10-Статистика!$C$10,0.000001))))) -> 0.11433081 | AZ5: =IF(A5="","",MAX(0,MAX(0,MIN(1,(((IF(Статистика!$C$4="Параллельный режим (активная мощность)",F5,Q5)+Статистика!$J$4))-Статистика!$C$10)/MAX(Статистика!$G$10-Статистика!$C$10,0.000001)))-MAX(0,MIN(1,(((IF(Статистика!$C$4="Параллельный режим (активная мощность)",E5,P5)+Статистика!$J$4))-Статистика!$C$10)/MAX(Статистика!$G$10-Статистика!$C$10,0.000001))))) -> 0.0674533 | BA5: =IF(A5="","",MAX(0,MAX(0,MIN(1,(((IF(Статистика!$C$4="Параллельный режим (активная мощность)",G5,R5)+Статистика!$J$4))-Статистика!$C$10)/MAX(Статистика!$G$10-Статистика!$C$10,0.000001)))-MAX(0,MIN(1,(((IF(Статистика!$C$4="Параллельный режим (активная мощность)",F5,Q5)+Статистика!$J$4))-Статистика!$C$10)/MAX(Статистика!$G$10-Статистика!$C$10,0.000001))))) -> 0.061160194 | BB5: =IF(A5="","",MAX(0,MAX(0,MIN(1,(((IF(Статистика!$C$4="Параллельный режим (активная мощность)",H5,S5)+Статистика!$J$4))-Статистика!$C$10)/MAX(Статистика!$G$10-Статистика!$C$10,0.000001)))-MAX(0,MIN(1,(((IF(Статистика!$C$4="Параллельный режим (активная мощность)",G5,R5)+Статистика!$J$4))-Статистика!$C$10)/MAX(Статистика!$G$10-Статистика!$C$10,0.000001))))) -> 0.11718894 | BC5: =IF(A5="","",MAX(0,MAX(0,MIN(1,(((IF(Статистика!$C$4="Параллельный режим (активная мощность)",J5,U5)+Статистика!$J$4))-Статистика!$C$10)/MAX(Статистика!$G$10-Статистика!$C$10,0.000001)))-MAX(0,MIN(1,(((IF(Статистика!$C$4="Параллельный режим (активная мощность)",H5,S5)+Статистика!$J$4))-Статистика!$C$10)/MAX(Статистика!$G$10-Статистика!$C$10,0.000001))))) -> 0.033540629 | BD5: =IF(A5="","",MAX(0,1-MAX(0,MIN(1,(((IF(Статистика!$C$4="Параллельный режим (активная мощность)",J5,U5)+Статистика!$J$4))-Статистика!$C$10)/MAX(Статистика!$G$10-Статистика!$C$10,0.000001))))) -> 0.15972694 | BE5: =IF(A5="",NA(),IF(Статистика!$B$8="Вкл",(((IF(Статистика!$C$4="Параллельный режим (активная мощность)",F5,Q5)+Статистика!$J$4))-Статистика!$C$10)/MAX(Статистика!$G$10-Статистика!$C$10,0.000001),NA())) -> 0.6283833 | BF5: =IF(A5="",NA(),IF(Статистика!$D$8="Вкл",(((IF(Статистика!$C$4="Параллельный режим (активная мощность)",E5,P5)+Статистика!$J$4))-Статистика!$C$10)/MAX(Статистика!$G$10-Статистика!$C$10,0.000001),NA())) -> 0.56093 | BG5: =IF(A5="",NA(),IF(Статистика!$D$8="Вкл",(((IF(Статистика!$C$4="Параллельный режим (активная мощность)",G5,R5)+Статистика!$J$4))-Статистика!$C$10)/MAX(Статистика!$G$10-Статистика!$C$10,0.000001),NA())) -> 0.68954349 | BH5: =IF(A5="",NA(),IF(Статистика!$F$8="Вкл",(((IF(Статистика!$C$4="Параллельный режим (активная мощность)",D5,O5)+Статистика!$J$4))-Статистика!$C$10)/MAX(Статистика!$G$10-Статистика!$C$10,0.000001),NA())) -> 0.44659919 | BI5: =IF(A5="",NA(),IF(Статистика!$F$8="Вкл",(((IF(Статистика!$C$4="Параллельный режим (активная мощность)",H5,S5)+Статистика!$J$4))-Статистика!$C$10)/MAX(Статистика!$G$10-Статистика!$C$10,0.000001),NA())) -> 0.80673243 | BJ5: =IF(A5="",NA(),IF(Статистика!$H$8="Вкл",(((IF(Статистика!$C$4="Параллельный режим (активная мощность)",B5,M5)+Статистика!$J$4))-Статистика!$C$10)/MAX(Статистика!$G$10-Статистика!$C$10,0.000001),NA())) -> -1.2344864 | BK5: =IF(A5="",NA(),IF(Статистика!$H$8="Вкл",(((IF(Статистика!$C$4="Параллельный режим (активная мощность)",J5,U5)+Статистика!$J$4))-Статистика!$C$10)/MAX(Статистика!$G$10-Статистика!$C$10,0.000001),NA())) -> 0.84027306 | BL5: =IF(A5="",NA(),IF(Статистика!$J$8="Вкл",(((IF(Статистика!$C$4="Параллельный режим (активная мощность)",K5,V5)+Статистика!$J$4))-Статистика!$C$10)/MAX(Статистика!$G$10-Статистика!$C$10,0.000001),NA())) -> #N/A | BM5: =IF(AND(A5<>"",Статистика!$C$6="Вкл",Статистика!$B$6>0),(Статистика!$B$6-Статистика!$C$10)/MAX(Статистика!$G$10-Статистика!$C$10,0.000001),NA()) -> #N/A | BN5: =IF(AND(A5<>"",Статистика!$F$6="Вкл",Статистика!$E$6>0),(Статистика!$E$6-Статистика!$C$10)/MAX(Статистика!$G$10-Статистика!$C$10,0.000001),NA()) -> #N/A | BO5: =IF(AND(A5<>"",Статистика!$I$6="Вкл",Статистика!$H$6>0),(Статистика!$H$6-Статистика!$C$10)/MAX(Статистика!$G$10-Статистика!$C$10,0.000001),NA()) -> #N/A | BP5: =IF(AND(A5<>"",Статистика!$L$6="Вкл",Статистика!$K$6>0),(Статистика!$K$6-Статистика!$C$10)/MAX(Статистика!$G$10-Статистика!$C$10,0.000001),NA()) -> #N/A | BQ5: =IF(AND(A5<>"",Статистика!$M$6="Вкл",Статистика!$O$6>0),(Статистика!$O$6-Статистика!$C$10)/MAX(Статистика!$G$10-Статистика!$C$10,0.000001),NA()) -> #N/A | BR5: =IF(A5="",NA(),1) -> 1 | BT5: =IF(Y5="","",MAX(0,MIN(1,(((IF(Статистика!$C$4="Параллельный режим (активная мощность)",Z5,AK5)+Статистика!$J$4))-Статистика!$C$10)/MAX(Статистика!$G$10-Статистика!$C$10,0.000001)))) -> 0.52821157 | BU5: =IF(Y5="","",MAX(0,MAX(0,MIN(1,(((IF(Статистика!$C$4="Параллельный режим (активная мощность)",AB5,AM5)+Статистика!$J$4))-Статистика!$C$10)/MAX(Статистика!$G$10-Статистика!$C$10,0.000001)))-MAX(0,MIN(1,(((IF(Статистика!$C$4="Параллельный режим (активная мощность)",Z5,AK5)+Статистика!$J$4))-Статистика!$C$10)/MAX(Статистика!$G$10-Статистика!$C$10,0.000001))))) -> 0.022328515 | BV5: =IF(Y5="","",MAX(0,MAX(0,MIN(1,(((IF(Статистика!$C$4="Параллельный режим (активная мощность)",AC5,AN5)+Статистика!$J$4))-Статистика!$C$10)/MAX(Статистика!$G$10-Статистика!$C$10,0.000001)))-MAX(0,MIN(1,(((IF(Статистика!$C$4="Параллельный режим (активная мощность)",AB5,AM5)+Статистика!$J$4))-Статистика!$C$10)/MAX(Статистика!$G$10-Статистика!$C$10,0.000001))))) -> 0.054493142 | BW5: =IF(Y5="","",MAX(0,MAX(0,MIN(1,(((IF(Статистика!$C$4="Параллельный режим (активная мощность)",AD5,AO5)+Статистика!$J$4))-Статистика!$C$10)/MAX(Статистика!$G$10-Статистика!$C$10,0.000001)))-MAX(0,MIN(1,(((IF(Статистика!$C$4="Параллельный режим (активная мощность)",AC5,AN5)+Статистика!$J$4))-Статистика!$C$10)/MAX(Статистика!$G$10-Статистика!$C$10,0.000001))))) -> 0.028223297 | BX5: =IF(Y5="","",MAX(0,MAX(0,MIN(1,(((IF(Статистика!$C$4="Параллельный режим (активная мощность)",AE5,AP5)+Статистика!$J$4))-Статистика!$C$10)/MAX(Статистика!$G$10-Статистика!$C$10,0.000001)))-MAX(0,MIN(1,(((IF(Статистика!$C$4="Параллельный режим (активная мощность)",AD5,AO5)+Статистика!$J$4))-Статистика!$C$10)/MAX(Статистика!$G$10-Статистика!$C$10,0.000001))))) -> 0.010552661 | BY5: =IF(Y5="","",MAX(0,MAX(0,MIN(1,(((IF(Статистика!$C$4="Параллельный режим (активная мощность)",AF5,AQ5)+Статистика!$J$4))-Статистика!$C$10)/MAX(Статистика!$G$10-Статистика!$C$10,0.000001)))-MAX(0,MIN(1,(((IF(Статистика!$C$4="Параллельный режим (активная мощность)",AE5,AP5)+Статистика!$J$4))-Статистика!$C$10)/MAX(Статистика!$G$10-Статистика!$C$10,0.000001))))) -> 0.15580193 | BZ5: =IF(Y5="","",MAX(0,MAX(0,MIN(1,(((IF(Статистика!$C$4="Параллельный режим (активная мощность)",AH5,AS5)+Статистика!$J$4))-Статистика!$C$10)/MAX(Статистика!$G$10-Статистика!$C$10,0.000001)))-MAX(0,MIN(1,(((IF(Статистика!$C$4="Параллельный режим (активная мощность)",AF5,AQ5)+Статистика!$J$4))-Статистика!$C$10)/MAX(Статистика!$G$10-Статистика!$C$10,0.000001))))) -> 0.032504791 | CA5: =IF(Y5="","",MAX(0,1-MAX(0,MIN(1,(((IF(Статистика!$C$4="Параллельный режим (активная мощность)",AH5,AS5)+Статистика!$J$4))-Статистика!$C$10)/MAX(Статистика!$G$10-Статистика!$C$10,0.000001))))) -> 0.1678841 | CB5: =IF(Y5="",NA(),IF(Статистика!$B$8="Вкл",(((IF(Статистика!$C$4="Параллельный режим (активная мощность)",AD5,AO5)+Статистика!$J$4))-Статистика!$C$10)/MAX(Статистика!$G$10-Статистика!$C$10,0.000001),NA())) -> 0.63325652 | CC5: =IF(Y5="",NA(),IF(Статистика!$D$8="Вкл",(((IF(Статистика!$C$4="Параллельный режим (активная мощность)",AC5,AN5)+Статистика!$J$4))-Статистика!$C$10)/MAX(Статистика!$G$10-Статистика!$C$10,0.000001),NA())) -> 0.60503323 | CD5: =IF(Y5="",NA(),IF(Статистика!$D$8="Вкл",(((IF(Статистика!$C$4="Параллельный режим (активная мощность)",AE5,AP5)+Статистика!$J$4))-Статистика!$C$10)/MAX(Статистика!$G$10-Статистика!$C$10,0.000001),NA())) -> 0.64380918 | CE5: =IF(Y5="",NA(),IF(Статистика!$F$8="Вкл",(((IF(Статистика!$C$4="Параллельный режим (активная мощность)",AB5,AM5)+Статистика!$J$4))-Статистика!$C$10)/MAX(Статистика!$G$10-Статистика!$C$10,0.000001),NA())) -> 0.55054008 | CF5: =IF(Y5="",NA(),IF(Статистика!$F$8="Вкл",(((IF(Статистика!$C$4="Параллельный режим (активная мощность)",AF5,AQ5)+Статистика!$J$4))-Статистика!$C$10)/MAX(Статистика!$G$10-Статистика!$C$10,0.000001),NA())) -> 0.79961111 | CG5: =IF(Y5="",NA(),IF(Статистика!$H$8="Вкл",(((IF(Статистика!$C$4="Параллельный режим (активная мощность)",Z5,AK5)+Статистика!$J$4))-Статистика!$C$10)/MAX(Статистика!$G$10-Статистика!$C$10,0.000001),NA())) -> 0.52821157 | CH5: =IF(Y5="",NA(),IF(Статистика!$H$8="Вкл",(((IF(Статистика!$C$4="Параллельный режим (активная мощность)",AH5,AS5)+Статистика!$J$4))-Статистика!$C$10)/MAX(Статистика!$G$10-Статистика!$C$10,0.000001),NA())) -> 0.8321159 | CI5: =IF(Y5="",NA(),IF(Статистика!$J$8="Вкл",(((IF(Статистика!$C$4="Параллельный режим (активная мощность)",AI5,AT5)+Статистика!$J$4))-Статистика!$C$10)/MAX(Статистика!$G$10-Статистика!$C$10,0.000001),NA())) -> #N/A | CJ5: =IF(AND(Y5<>"",Статистика!$C$6="Вкл",Статистика!$B$6>0),(Статистика!$B$6-Статистика!$C$10)/MAX(Статистика!$G$10-Статистика!$C$10,0.000001),NA()) -> #N/A | CK5: =IF(AND(Y5<>"",Статистика!$F$6="Вкл",Статистика!$E$6>0),(Статистика!$E$6-Статистика!$C$10)/MAX(Статистика!$G$10-Статистика!$C$10,0.000001),NA()) -> #N/A | CL5: =IF(AND(Y5<>"",Статистика!$I$6="Вкл",Статистика!$H$6>0),(Статистика!$H$6-Статистика!$C$10)/MAX(Статистика!$G$10-Статистика!$C$10,0.000001),NA()) -> #N/A | CM5: =IF(AND(Y5<>"",Статистика!$L$6="Вкл",Статистика!$K$6>0),(Статистика!$K$6-Статистика!$C$10)/MAX(Статистика!$G$10-Статистика!$C$10,0.000001),NA()) -> #N/A | CN5: =IF(AND(Y5<>"",Статистика!$M$6="Вкл",Статистика!$O$6>0),(Статистика!$O$6-Статистика!$C$10)/MAX(Статистика!$G$10-Статистика!$C$10,0.000001),NA()) -> #N/A | CO5: =IF(Y5="",NA(),1) -> 1
A6: 00:20 | B6: 2313.9931 | C6: 5701.7546 | D6: 7377.8602 | E6: 7678.7573 | F6: 7908.5602 | G6: 8087.514 | H6: 8401.3414 | I6: 8489.8241 | J6: 8558.0745 | K6: 8670.17 | L6: 2026-07-08 00:20:51 | M6: 2869.0522 | N6: 6576.4727 | O6: 8431.473 | P6: 8745.7182 | Q6: 8950.8459 | R6: 9178.9856 | S6: 9456.6225 | T6: 9590.5439 | U6: 9727.6675 | V6: 9845.73 | W6: 2026-07-08 00:20:51 | Y6: 00:20 | Z6: 7611.585 | AA6: 7648.0968 | AB6: 7693.7366 | AC6: 7812.1308 | AD6: 7905.0527 | AE6: 7966.1439 | AF6: 8375.5538 | AG6: 8435.5595 | AH6: 8483.5641 | AI6: 8591.87 | AJ6: 2026-07-05 00:23:39 | AK6: 8719.5547 | AL6: 8743.6159 | AM6: 8773.6923 | AN6: 8974.6134 | AO6: 9022.2487 | AP6: 9065.5859 | AQ6: 9455.3227 | AR6: 9526.7196 | AS6: 9583.8372 | AT6: 9676.94 | AU6: 2026-07-05 00:23:39 | AW6: =IF(A6="","",MAX(0,MIN(1,(((IF(Статистика!$C$4="Параллельный режим (активная мощность)",B6,M6)+Статистика!$J$4))-Статистика!$C$10)/MAX(Статистика!$G$10-Статистика!$C$10,0.000001)))) -> 0 | AX6: =IF(A6="","",MAX(0,MAX(0,MIN(1,(((IF(Статистика!$C$4="Параллельный режим (активная мощность)",D6,O6)+Статистика!$J$4))-Статистика!$C$10)/MAX(Статистика!$G$10-Статистика!$C$10,0.000001)))-MAX(0,MIN(1,(((IF(Статистика!$C$4="Параллельный режим (активная мощность)",B6,M6)+Статистика!$J$4))-Статистика!$C$10)/MAX(Статистика!$G$10-Статистика!$C$10,0.000001))))) -> 0.45928674 | AY6: =IF(A6="","",MAX(0,MAX(0,MIN(1,(((IF(Статистика!$C$4="Параллельный режим (активная мощность)",E6,P6)+Статистика!$J$4))-Статистика!$C$10)/MAX(Статистика!$G$10-Статистика!$C$10,0.000001)))-MAX(0,MIN(1,(((IF(Статистика!$C$4="Параллельный режим (активная мощность)",D6,O6)+Статистика!$J$4))-Статистика!$C$10)/MAX(Статистика!$G$10-Статистика!$C$10,0.000001))))) -> 0.10029902 | AZ6: =IF(A6="","",MAX(0,MAX(0,MIN(1,(((IF(Статистика!$C$4="Параллельный режим (активная мощность)",F6,Q6)+Статистика!$J$4))-Статистика!$C$10)/MAX(Статистика!$G$10-Статистика!$C$10,0.000001)))-MAX(0,MIN(1,(((IF(Статистика!$C$4="Параллельный режим (активная мощность)",E6,P6)+Статистика!$J$4))-Статистика!$C$10)/MAX(Статистика!$G$10-Статистика!$C$10,0.000001))))) -> 0.076600958 | BA6: =IF(A6="","",MAX(0,MAX(0,MIN(1,(((IF(Статистика!$C$4="Параллельный режим (активная мощность)",G6,R6)+Статистика!$J$4))-Статистика!$C$10)/MAX(Статистика!$G$10-Статистика!$C$10,0.000001)))-MAX(0,MIN(1,(((IF(Статистика!$C$4="Параллельный режим (активная мощность)",F6,Q6)+Статистика!$J$4))-Статистика!$C$10)/MAX(Статистика!$G$10-Статистика!$C$10,0.000001))))) -> 0.059651256 | BB6: =IF(A6="","",MAX(0,MAX(0,MIN(1,(((IF(Статистика!$C$4="Параллельный режим (активная мощность)",H6,S6)+Статистика!$J$4))-Статистика!$C$10)/MAX(Статистика!$G$10-Статистика!$C$10,0.000001)))-MAX(0,MIN(1,(((IF(Статистика!$C$4="Параллельный режим (активная мощность)",G6,R6)+Статистика!$J$4))-Статистика!$C$10)/MAX(Статистика!$G$10-Статистика!$C$10,0.000001))))) -> 0.10460915 | BC6: =IF(A6="","",MAX(0,MAX(0,MIN(1,(((IF(Статистика!$C$4="Параллельный режим (активная мощность)",J6,U6)+Статистика!$J$4))-Статистика!$C$10)/MAX(Статистика!$G$10-Статистика!$C$10,0.000001)))-MAX(0,MIN(1,(((IF(Статистика!$C$4="Параллельный режим (активная мощность)",H6,S6)+Статистика!$J$4))-Статистика!$C$10)/MAX(Статистика!$G$10-Статистика!$C$10,0.000001))))) -> 0.052244378 | BD6: =IF(A6="","",MAX(0,1-MAX(0,MIN(1,(((IF(Статистика!$C$4="Параллельный режим (активная мощность)",J6,U6)+Статистика!$J$4))-Статистика!$C$10)/MAX(Статистика!$G$10-Статистика!$C$10,0.000001))))) -> 0.14730849 | BE6: =IF(A6="",NA(),IF(Статистика!$B$8="Вкл",(((IF(Статистика!$C$4="Параллельный режим (активная мощность)",F6,Q6)+Статистика!$J$4))-Статистика!$C$10)/MAX(Статистика!$G$10-Статистика!$C$10,0.000001),NA())) -> 0.63618673 | BF6: =IF(A6="",NA(),IF(Статистика!$D$8="Вкл",(((IF(Статистика!$C$4="Параллельный режим (активная мощность)",E6,P6)+Статистика!$J$4))-Статистика!$C$10)/MAX(Статистика!$G$10-Статистика!$C$10,0.000001),NA())) -> 0.55958577 | BG6: =IF(A6="",NA(),IF(Статистика!$D$8="Вкл",(((IF(Статистика!$C$4="Параллельный режим (активная мощность)",G6,R6)+Статистика!$J$4))-Статистика!$C$10)/MAX(Статистика!$G$10-Статистика!$C$10,0.000001),NA())) -> 0.69583798 | BH6: =IF(A6="",NA(),IF(Статистика!$F$8="Вкл",(((IF(Статистика!$C$4="Параллельный режим (активная мощность)",D6,O6)+Статистика!$J$4))-Статистика!$C$10)/MAX(Статистика!$G$10-Статистика!$C$10,0.000001),NA())) -> 0.45928674 | BI6: =IF(A6="",NA(),IF(Статистика!$F$8="Вкл",(((IF(Статистика!$C$4="Параллельный режим (активная мощность)",H6,S6)+Статистика!$J$4))-Статистика!$C$10)/MAX(Статистика!$G$10-Статистика!$C$10,0.000001),NA())) -> 0.80044713 | BJ6: =IF(A6="",NA(),IF(Статистика!$H$8="Вкл",(((IF(Статистика!$C$4="Параллельный режим (активная мощность)",B6,M6)+Статистика!$J$4))-Статистика!$C$10)/MAX(Статистика!$G$10-Статистика!$C$10,0.000001),NA())) -> -1.228669 | BK6: =IF(A6="",NA(),IF(Статистика!$H$8="Вкл",(((IF(Статистика!$C$4="Параллельный режим (активная мощность)",J6,U6)+Статистика!$J$4))-Статистика!$C$10)/MAX(Статистика!$G$10-Статистика!$C$10,0.000001),NA())) -> 0.85269151 | BL6: =IF(A6="",NA(),IF(Статистика!$J$8="Вкл",(((IF(Статистика!$C$4="Параллельный режим (активная мощность)",K6,V6)+Статистика!$J$4))-Статистика!$C$10)/MAX(Статистика!$G$10-Статистика!$C$10,0.000001),NA())) -> #N/A | BM6: =IF(AND(A6<>"",Статистика!$C$6="Вкл",Статистика!$B$6>0),(Статистика!$B$6-Статистика!$C$10)/MAX(Статистика!$G$10-Статистика!$C$10,0.000001),NA()) -> #N/A | BN6: =IF(AND(A6<>"",Статистика!$F$6="Вкл",Статистика!$E$6>0),(Статистика!$E$6-Статистика!$C$10)/MAX(Статистика!$G$10-Статистика!$C$10,0.000001),NA()) -> #N/A | BO6: =IF(AND(A6<>"",Статистика!$I$6="Вкл",Статистика!$H$6>0),(Статистика!$H$6-Статистика!$C$10)/MAX(Статистика!$G$10-Статистика!$C$10,0.000001),NA()) -> #N/A | BP6: =IF(AND(A6<>"",Статистика!$L$6="Вкл",Статистика!$K$6>0),(Статистика!$K$6-Статистика!$C$10)/MAX(Статистика!$G$10-Статистика!$C$10,0.000001),NA()) -> #N/A | BQ6: =IF(AND(A6<>"",Статистика!$M$6="Вкл",Статистика!$O$6>0),(Статистика!$O$6-Статистика!$C$10)/MAX(Статистика!$G$10-Статистика!$C$10,0.000001),NA()) -> #N/A | BR6: =IF(A6="",NA(),1) -> 1 | BT6: =IF(Y6="","",MAX(0,MIN(1,(((IF(Статистика!$C$4="Параллельный режим (активная мощность)",Z6,AK6)+Статистика!$J$4))-Статистика!$C$10)/MAX(Статистика!$G$10-Статистика!$C$10,0.000001)))) -> 0.53719499 | BU6: =IF(Y6="","",MAX(0,MAX(0,MIN(1,(((IF(Статистика!$C$4="Параллельный режим (активная мощность)",AB6,AM6)+Статистика!$J$4))-Статистика!$C$10)/MAX(Статистика!$G$10-Статистика!$C$10,0.000001)))-MAX(0,MIN(1,(((IF(Статистика!$C$4="Параллельный режим (активная мощность)",Z6,AK6)+Статистика!$J$4))-Статистика!$C$10)/MAX(Статистика!$G$10-Статистика!$C$10,0.000001))))) -> 0.027383895 | BV6: =IF(Y6="","",MAX(0,MAX(0,MIN(1,(((IF(Статистика!$C$4="Параллельный режим (активная мощность)",AC6,AN6)+Статистика!$J$4))-Статистика!$C$10)/MAX(Статистика!$G$10-Статистика!$C$10,0.000001)))-MAX(0,MIN(1,(((IF(Статистика!$C$4="Параллельный режим (активная мощность)",AB6,AM6)+Статистика!$J$4))-Статистика!$C$10)/MAX(Статистика!$G$10-Статистика!$C$10,0.000001))))) -> 0.039464722 | BW6: =IF(Y6="","",MAX(0,MAX(0,MIN(1,(((IF(Статистика!$C$4="Параллельный режим (активная мощность)",AD6,AO6)+Статистика!$J$4))-Статистика!$C$10)/MAX(Статистика!$G$10-Статистика!$C$10,0.000001)))-MAX(0,MIN(1,(((IF(Статистика!$C$4="Параллельный режим (активная мощность)",AC6,AN6)+Статистика!$J$4))-Статистика!$C$10)/MAX(Статистика!$G$10-Статистика!$C$10,0.000001))))) -> 0.030973978 | BX6: =IF(Y6="","",MAX(0,MAX(0,MIN(1,(((IF(Статистика!$C$4="Параллельный режим (активная мощность)",AE6,AP6)+Статистика!$J$4))-Статистика!$C$10)/MAX(Статистика!$G$10-Статистика!$C$10,0.000001)))-MAX(0,MIN(1,(((IF(Статистика!$C$4="Параллельный режим (активная мощность)",AD6,AO6)+Статистика!$J$4))-Статистика!$C$10)/MAX(Статистика!$G$10-Статистика!$C$10,0.000001))))) -> 0.020363714 | BY6: =IF(Y6="","",MAX(0,MAX(0,MIN(1,(((IF(Статистика!$C$4="Параллельный режим (активная мощность)",AF6,AQ6)+Статистика!$J$4))-Статистика!$C$10)/MAX(Статистика!$G$10-Статистика!$C$10,0.000001)))-MAX(0,MIN(1,(((IF(Статистика!$C$4="Параллельный режим (активная мощность)",AE6,AP6)+Статистика!$J$4))-Статистика!$C$10)/MAX(Статистика!$G$10-Статистика!$C$10,0.000001))))) -> 0.13646996 | BZ6: =IF(Y6="","",MAX(0,MAX(0,MIN(1,(((IF(Статистика!$C$4="Параллельный режим (активная мощность)",AH6,AS6)+Статистика!$J$4))-Статистика!$C$10)/MAX(Статистика!$G$10-Статистика!$C$10,0.000001)))-MAX(0,MIN(1,(((IF(Статистика!$C$4="Параллельный режим (активная мощность)",AF6,AQ6)+Статистика!$J$4))-Статистика!$C$10)/MAX(Статистика!$G$10-Статистика!$C$10,0.000001))))) -> 0.036003434 | CA6: =IF(Y6="","",MAX(0,1-MAX(0,MIN(1,(((IF(Статистика!$C$4="Параллельный режим (активная мощность)",AH6,AS6)+Статистика!$J$4))-Статистика!$C$10)/MAX(Статистика!$G$10-Статистика!$C$10,0.000001))))) -> 0.1721453 | CB6: =IF(Y6="",NA(),IF(Статистика!$B$8="Вкл",(((IF(Статистика!$C$4="Параллельный режим (активная мощность)",AD6,AO6)+Статистика!$J$4))-Статистика!$C$10)/MAX(Статистика!$G$10-Статистика!$C$10,0.000001),NA())) -> 0.63501758 | CC6: =IF(Y6="",NA(),IF(Статистика!$D$8="Вкл",(((IF(Статистика!$C$4="Параллельный режим (активная мощность)",AC6,AN6)+Статистика!$J$4))-Статистика!$C$10)/MAX(Статистика!$G$10-Статистика!$C$10,0.000001),NA())) -> 0.60404361 | CD6: =IF(Y6="",NA(),IF(Статистика!$D$8="Вкл",(((IF(Статистика!$C$4="Параллельный режим (активная мощность)",AE6,AP6)+Статистика!$J$4))-Статистика!$C$10)/MAX(Статистика!$G$10-Статистика!$C$10,0.000001),NA())) -> 0.6553813 | CE6: =IF(Y6="",NA(),IF(Статистика!$F$8="Вкл",(((IF(Статистика!$C$4="Параллельный режим (активная мощность)",AB6,AM6)+Статистика!$J$4))-Статистика!$C$10)/MAX(Статистика!$G$10-Статистика!$C$10,0.000001),NA())) -> 0.56457888 | CF6: =IF(Y6="",NA(),IF(Статистика!$F$8="Вкл",(((IF(Статистика!$C$4="Параллельный режим (активная мощность)",AF6,AQ6)+Статистика!$J$4))-Статистика!$C$10)/MAX(Статистика!$G$10-Статистика!$C$10,0.000001),NA())) -> 0.79185126 | CG6: =IF(Y6="",NA(),IF(Статистика!$H$8="Вкл",(((IF(Статистика!$C$4="Параллельный режим (активная мощность)",Z6,AK6)+Статистика!$J$4))-Статистика!$C$10)/MAX(Статистика!$G$10-Статистика!$C$10,0.000001),NA())) -> 0.53719499 | CH6: =IF(Y6="",NA(),IF(Статистика!$H$8="Вкл",(((IF(Статистика!$C$4="Параллельный режим (активная мощность)",AH6,AS6)+Статистика!$J$4))-Статистика!$C$10)/MAX(Статистика!$G$10-Статистика!$C$10,0.000001),NA())) -> 0.8278547 | CI6: =IF(Y6="",NA(),IF(Статистика!$J$8="Вкл",(((IF(Статистика!$C$4="Параллельный режим (активная мощность)",AI6,AT6)+Статистика!$J$4))-Статистика!$C$10)/MAX(Статистика!$G$10-Статистика!$C$10,0.000001),NA())) -> #N/A | CJ6: =IF(AND(Y6<>"",Статистика!$C$6="Вкл",Статистика!$B$6>0),(Статистика!$B$6-Статистика!$C$10)/MAX(Статистика!$G$10-Статистика!$C$10,0.000001),NA()) -> #N/A | CK6: =IF(AND(Y6<>"",Статистика!$F$6="Вкл",Статистика!$E$6>0),(Статистика!$E$6-Статистика!$C$10)/MAX(Статистика!$G$10-Статистика!$C$10,0.000001),NA()) -> #N/A | CL6: =IF(AND(Y6<>"",Статистика!$I$6="Вкл",Статистика!$H$6>0),(Статистика!$H$6-Статистика!$C$10)/MAX(Статистика!$G$10-Статистика!$C$10,0.000001),NA()) -> #N/A | CM6: =IF(AND(Y6<>"",Статистика!$L$6="Вкл",Статистика!$K$6>0),(Статистика!$K$6-Статистика!$C$10)/MAX(Статистика!$G$10-Статистика!$C$10,0.000001),NA()) -> #N/A | CN6: =IF(AND(Y6<>"",Статистика!$M$6="Вкл",Статистика!$O$6>0),(Статистика!$O$6-Статистика!$C$10)/MAX(Статистика!$G$10-Статистика!$C$10,0.000001),NA()) -> #N/A | CO6: =IF(Y6="",NA(),1) -> 1
